#VRML_SIM R2021a utf8
WorldInfo {
  info [
    ""
    ""
  ]
  physics "flippy_physics"
  basicTimeStep 16
  coordinateSystem "NUE"
}
Viewpoint {
  orientation -0.07237226055216188 -0.9615506766747227 -0.26491989749536177 1.6021124575527574
  position -0.7673065553099321 0.28881503520980834 0.1414097586585502
}
Background {
  skyColor [
    0.7 0.7 0.7
    0 0 0
    0 0 0
    0 0 0
    0 0 0
  ]
}
DEF FLOOR RectangleArena {
}
DEF real_floor Solid {
  children [
    DEF floor_shape Shape {
      geometry Box {
        size 1 0.01 1
      }
    }
    DEF floor_connector Connector {
      name "floor_connector"
      model "flippy_stick"
      boundingObject USE floor_shape
      physics Physics {
      }
      type "passive"
      autoLock TRUE
      distanceTolerance 10
      axisTolerance 3.14
      rotationTolerance 3.141592653589793
      numberOfRotations 0
      snap FALSE
    }
  ]
  boundingObject USE floor_shape
}
Robot {
  translation 0 0.08 0
  rotation 1 0 0 -0.4
  children [
    Solid {
      children [
        DEF BODY Shape {
          appearance DEF RED PBRAppearance {
            baseColor 1 0.2 0.2
            roughness 1
            metalness 0
          }
          geometry Cylinder {
            height 0.1
            radius 0.01
          }
        }
      ]
      name "solid(2)"
      boundingObject USE BODY
      physics Physics {
      }
    }
    HingeJoint {
      jointParameters DEF HINGE_PARAMS HingeJointParameters {
        anchor 0 0.05 0
      }
      device [
        RotationalMotor {
          name "M1"
        }
      ]
      endPoint DEF F000_S1 Solid {
        translation 0 0.04991302955174124 3.701909857734677e-05
        rotation -1 0 0 0.0005667977202639379
        children [
          DEF S1 Shape {
            appearance DEF GREEN PBRAppearance {
              baseColor 0.2 1 0.2
              roughness 1
              metalness 0
            }
            geometry Sphere {
              radius 0.03
            }
          }
          DEF BUMPER TouchSensor {
            name "T1"
            boundingObject USE S1
            physics DEF BUMP_PHYSICS Physics {
            }
          }
        ]
        boundingObject USE S1
        physics DEF S_PHYSICS Physics {
        }
      }
    }
    HingeJoint {
      jointParameters HingeJointParameters {
        anchor 0 -0.05 0
      }
      device [
        RotationalMotor {
          name "M2"
        }
      ]
      endPoint DEF F000_S2 Solid {
        translation 0 -0.05034385278663667 -0.00015123474696968143
        rotation -1 0 0 0.0005051759181945691
        children [
          USE S1
          TouchSensor {
            name "T2"
            boundingObject USE S1
            physics USE BUMP_PHYSICS
          }
        ]
        name "solid(1)"
        boundingObject USE S1
        physics USE S_PHYSICS
      }
    }
    Receiver {
      name "R1"
    }
    Emitter {
      name "E1"
    }
  ]
  name "F000"
  boundingObject USE BODY
  physics USE S_PHYSICS
  controller "flippy_controller"
  controllerArgs [
    "0"
  ]
}
