#VRML_SIM R2021a utf8
WorldInfo {
  info [
    ""
    ""
  ]
  title "FLIPPY SIM AUTO"
  physics "flippy_physics"
  basicTimeStep 16
  coordinateSystem "NUE"
}
Viewpoint {
  orientation -0.09038572960142734 -0.9648540423900209 -0.2467531089329039 1.983834912716192
  position -0.9712672294084008 0.48633972408115617 -0.3456696747452824
}
Background {
  skyColor [
    0.7 0.7 0.7
    0 0 0
    0 0 0
    0 0 0
    0 0 0
  ]
}
DEF FLOOR RectangleArena {
}
DEF real_floor Solid {
  children [
    DEF floor_shape Shape {
      geometry Box {
        size 1 0.01 1
      }
    }
    DEF floor_connector Connector {
      name "floor_connector"
      model "flippy_stick"
      boundingObject USE floor_shape
      physics Physics {
      }
      type "passive"
      autoLock TRUE
      distanceTolerance 10
      axisTolerance 3.14
      rotationTolerance 3.141592653589793
      numberOfRotations 0
      snap FALSE
    }
  ]
  boundingObject USE floor_shape
}
Robot {
  translation -0.15068842 0.03000609 -0.00663518
  rotation 0.8709509182164061 -0.3462389674876431 0.34865896726040146 1.69012
  children [
    Solid {
      children [
        DEF BODY Shape {
          appearance DEF RED PBRAppearance {
            baseColor 1 0.2 0.2
            roughness 1
            metalness 0
          }
          geometry Cylinder {
            height 0.1
            radius 0.01
          }
        }
      ]
      name "solid(2)"
      boundingObject USE BODY
      physics Physics {
      }
    }
    HingeJoint {
      jointParameters DEF HINGE_PARAMS HingeJointParameters {
        anchor 0 0.05 0
      }
      device [
        RotationalMotor {
          name "M1"
        }
      ]
      endPoint DEF F000_S1 Solid {
        translation 0 0.04991302955174124 3.701909857734677e-05
        rotation -1 0 0 0.0005667977202639379
        children [
          DEF S1 Shape {
            appearance DEF GREEN PBRAppearance {
              baseColor 0.2 1 0.2
              roughness 1
              metalness 0
            }
            geometry Sphere {
              radius 0.03
            }
          }
          DEF BUMPER TouchSensor {
            name "T1"
            boundingObject USE S1
            physics DEF BUMP_PHYSICS Physics {
            }
          }
        ]
        boundingObject USE S1
        physics DEF S_PHYSICS Physics {
        }
      }
    }
    HingeJoint {
      jointParameters HingeJointParameters {
        anchor 0 -0.05 0
      }
      device [
        RotationalMotor {
          name "M2"
        }
      ]
      endPoint DEF F000_S2 Solid {
        translation 0 -0.05034385278663667 -0.00015123474696968143
        rotation -1 0 0 0.0005051759181945691
        children [
          USE S1
          TouchSensor {
            name "T2"
            boundingObject USE S1
            physics USE BUMP_PHYSICS
          }
        ]
        name "solid(1)"
        boundingObject USE S1
        physics USE S_PHYSICS
      }
    }
    Receiver {
      name "R1"
    }
    Emitter {
      name "E1"
    }
  ]
  name "F000"
  boundingObject USE BODY
  physics USE S_PHYSICS
  controller "flippy_controller"
  controllerArgs [
    "0"
  ]
}
Robot {
  translation -0.00828115 0.0299506 -0.00112324
  rotation 0.9934318126621877 -0.08161416021870874 0.08020201021492447 1.55993221
  children [
    Solid {
      children [
        DEF BODY Shape {
          appearance DEF RED PBRAppearance {
            baseColor 1 0.2 0.2
            roughness 1
            metalness 0
          }
          geometry Cylinder {
            height 0.1
            radius 0.01
          }
        }
      ]
      name "solid(2)"
      boundingObject USE BODY
      physics Physics {
      }
    }
    HingeJoint {
      jointParameters DEF HINGE_PARAMS HingeJointParameters {
        anchor 0 0.05 0
      }
      device [
        RotationalMotor {
          name "M1"
        }
      ]
      endPoint DEF F001_S1 Solid {
        translation 0 0.04991302955174124 3.701909857734677e-05
        rotation -1 0 0 0.0005667977202639379
        children [
          DEF S1 Shape {
            appearance DEF GREEN PBRAppearance {
              baseColor 0.2 1 0.2
              roughness 1
              metalness 0
            }
            geometry Sphere {
              radius 0.03
            }
          }
          DEF BUMPER TouchSensor {
            name "T1"
            boundingObject USE S1
            physics DEF BUMP_PHYSICS Physics {
            }
          }
        ]
        boundingObject USE S1
        physics DEF S_PHYSICS Physics {
        }
      }
    }
    HingeJoint {
      jointParameters HingeJointParameters {
        anchor 0 -0.05 0
      }
      device [
        RotationalMotor {
          name "M2"
        }
      ]
      endPoint DEF F001_S2 Solid {
        translation 0 -0.05034385278663667 -0.00015123474696968143
        rotation -1 0 0 0.0005051759181945691
        children [
          USE S1
          TouchSensor {
            name "T2"
            boundingObject USE S1
            physics USE BUMP_PHYSICS
          }
        ]
        name "solid(1)"
        boundingObject USE S1
        physics USE S_PHYSICS
      }
    }
    Receiver {
      name "R1"
    }
    Emitter {
      name "E1"
    }
  ]
  name "F001"
  boundingObject USE BODY
  physics USE S_PHYSICS
  controller "flippy_controller"
  controllerArgs [
    "0"
  ]
}
Robot {
  translation 0.14734011 0.0300669 -0.00674371
  rotation 0.9962180381483735 -0.06197329988481296 0.06090098988680602 1.55713171
  children [
    Solid {
      children [
        DEF BODY Shape {
          appearance DEF RED PBRAppearance {
            baseColor 1 0.2 0.2
            roughness 1
            metalness 0
          }
          geometry Cylinder {
            height 0.1
            radius 0.01
          }
        }
      ]
      name "solid(2)"
      boundingObject USE BODY
      physics Physics {
      }
    }
    HingeJoint {
      jointParameters DEF HINGE_PARAMS HingeJointParameters {
        anchor 0 0.05 0
      }
      device [
        RotationalMotor {
          name "M1"
        }
      ]
      endPoint DEF F002_S1 Solid {
        translation 0 0.04991302955174124 3.701909857734677e-05
        rotation -1 0 0 0.0005667977202639379
        children [
          DEF S1 Shape {
            appearance DEF GREEN PBRAppearance {
              baseColor 0.2 1 0.2
              roughness 1
              metalness 0
            }
            geometry Sphere {
              radius 0.03
            }
          }
          DEF BUMPER TouchSensor {
            name "T1"
            boundingObject USE S1
            physics DEF BUMP_PHYSICS Physics {
            }
          }
        ]
        boundingObject USE S1
        physics DEF S_PHYSICS Physics {
        }
      }
    }
    HingeJoint {
      jointParameters HingeJointParameters {
        anchor 0 -0.05 0
      }
      device [
        RotationalMotor {
          name "M2"
        }
      ]
      endPoint DEF F002_S2 Solid {
        translation 0 -0.05034385278663667 -0.00015123474696968143
        rotation -1 0 0 0.0005051759181945691
        children [
          USE S1
          TouchSensor {
            name "T2"
            boundingObject USE S1
            physics USE BUMP_PHYSICS
          }
        ]
        name "solid(1)"
        boundingObject USE S1
        physics USE S_PHYSICS
      }
    }
    Receiver {
      name "R1"
    }
    Emitter {
      name "E1"
    }
  ]
  name "F002"
  boundingObject USE BODY
  physics USE S_PHYSICS
  controller "flippy_controller"
  controllerArgs [
    "0"
  ]
}
Robot {
  translation 0.31170383 0.03007519 -0.00822538
  rotation 0.999327412677382 0.026155220070074647 -0.025702660068862154 1.55401575
  children [
    Solid {
      children [
        DEF BODY Shape {
          appearance DEF RED PBRAppearance {
            baseColor 1 0.2 0.2
            roughness 1
            metalness 0
          }
          geometry Cylinder {
            height 0.1
            radius 0.01
          }
        }
      ]
      name "solid(2)"
      boundingObject USE BODY
      physics Physics {
      }
    }
    HingeJoint {
      jointParameters DEF HINGE_PARAMS HingeJointParameters {
        anchor 0 0.05 0
      }
      device [
        RotationalMotor {
          name "M1"
        }
      ]
      endPoint DEF F003_S1 Solid {
        translation 0 0.04991302955174124 3.701909857734677e-05
        rotation -1 0 0 0.0005667977202639379
        children [
          DEF S1 Shape {
            appearance DEF GREEN PBRAppearance {
              baseColor 0.2 1 0.2
              roughness 1
              metalness 0
            }
            geometry Sphere {
              radius 0.03
            }
          }
          DEF BUMPER TouchSensor {
            name "T1"
            boundingObject USE S1
            physics DEF BUMP_PHYSICS Physics {
            }
          }
        ]
        boundingObject USE S1
        physics DEF S_PHYSICS Physics {
        }
      }
    }
    HingeJoint {
      jointParameters HingeJointParameters {
        anchor 0 -0.05 0
      }
      device [
        RotationalMotor {
          name "M2"
        }
      ]
      endPoint DEF F003_S2 Solid {
        translation 0 -0.05034385278663667 -0.00015123474696968143
        rotation -1 0 0 0.0005051759181945691
        children [
          USE S1
          TouchSensor {
            name "T2"
            boundingObject USE S1
            physics USE BUMP_PHYSICS
          }
        ]
        name "solid(1)"
        boundingObject USE S1
        physics USE S_PHYSICS
      }
    }
    Receiver {
      name "R1"
    }
    Emitter {
      name "E1"
    }
  ]
  name "F003"
  boundingObject USE BODY
  physics USE S_PHYSICS
  controller "flippy_controller"
  controllerArgs [
    "0"
  ]
}
