#VRML_SIM R2021a utf8
WorldInfo {
  info [
    ""
    ""
  ]
  physics "flippy_physics"
  basicTimeStep 16
  coordinateSystem "NUE"
}
Viewpoint {
  orientation -0.5891834562389339 0.791085161348425 0.16446009360535038 0.9410000667030044
  position 0.6635361447578698 0.7590602063775108 0.6485891290049746
}
Background {
  skyColor [
    0.7 0.7 0.7
    0 0 0
    0 0 0
    0 0 0
    0 0 0
  ]
}
DEF FLOOR RectangleArena {
}
DEF real_floor Solid {
  children [
    DEF floor_shape Shape {
      geometry Box {
        size 1 0.01 1
      }
    }
    DEF floor_connector Connector {
      name "floor_connector"
      model "flippy_stick"
      boundingObject USE floor_shape
      physics Physics {
      }
      type "passive"
      autoLock TRUE
      distanceTolerance 10
      axisTolerance 3.14
      rotationTolerance 3.141592653589793
      numberOfRotations 0
      snap FALSE
    }
  ]
  boundingObject USE floor_shape
}
DEF FLIPPY Robot {
  translation 0 0.08 0
  rotation 1 0 0 0.4
  children [
    Solid {
      children [
        DEF BODY Shape {
          appearance DEF RED PBRAppearance {
            baseColor 1 0.2 0.2
            roughness 1
            metalness 0
          }
          geometry Cylinder {
            height 0.1
            radius 0.01
          }
        }
      ]
      name "solid(2)"
      boundingObject USE BODY
      physics Physics {
      }
    }
    HingeJoint {
      jointParameters DEF HINGE_PARAMS HingeJointParameters {
        anchor 0 0.05 0
      }
      device [
        RotationalMotor {
          name "M1"
        }
      ]
      endPoint DEF SPHERE1 Solid {
        translation 0 0.04991302955174124 3.701909857734546e-05
        rotation -1 0 0 0.0005667977202639379
        children [
          DEF S1 Shape {
            appearance DEF GREEN PBRAppearance {
              baseColor 0.2 1 0.2
              roughness 1
              metalness 0
            }
            geometry Sphere {
              radius 0.03
            }
          }
          DEF BUMPER TouchSensor {
            name "T1"
            boundingObject USE S1
            physics DEF BUMP_PHYSICS Physics {
            }
          }
          DEF active_connector Connector {
            name "s1_connector"
            model "flippy_stick"
            boundingObject USE S1
            physics USE BUMP_PHYSICS
            type "active"
            distanceTolerance 10
            axisTolerance 3.141592653589793
            rotationTolerance 3.141592653589793
            numberOfRotations 0
            snap FALSE
          }
          Connector {
            name "s1_sym_connector"
            model "inter_flippy"
            boundingObject USE S1
            physics USE BUMP_PHYSICS
            autoLock TRUE
            distanceTolerance 0.05
            axisTolerance 3.14
            rotationTolerance 3.14
            numberOfRotations 0
            snap FALSE
          }
        ]
        boundingObject USE S1
        physics DEF S_PHYSICS Physics {
        }
      }
    }
    HingeJoint {
      jointParameters HingeJointParameters {
        anchor 0 -0.05 0
      }
      device [
        RotationalMotor {
          name "M2"
        }
      ]
      endPoint DEF SPHERE2 Solid {
        translation 0 -0.05034385278663667 -0.00015123474696968406
        rotation -1 0 0 0.0005051759577530935
        children [
          Connector {
            name "s2_connector"
            model "flippy_stick"
            boundingObject USE S1
            physics USE BUMP_PHYSICS
            translationStep 0.1
            type "active"
            distanceTolerance 10
            axisTolerance 3.14
            rotationTolerance 3.14
            numberOfRotations 0
            snap FALSE
          }
          USE S1
          TouchSensor {
            name "T2"
            boundingObject USE S1
            physics USE BUMP_PHYSICS
          }
          Connector {
            name "s2_sym_connector"
            model "inter_flippy"
            boundingObject USE S1
            physics USE BUMP_PHYSICS
            autoLock TRUE
            distanceTolerance 0.05
            axisTolerance 3.14
            rotationTolerance 3.14
            numberOfRotations 0
            snap FALSE
          }
        ]
        name "solid(1)"
        boundingObject USE S1
        physics USE S_PHYSICS
      }
    }
  ]
  name "FLIPPY"
  boundingObject USE S1
  physics USE S_PHYSICS
  controller "flippy_controller"
  controllerArgs [
    "0"
  ]
}
flippy {
  translation 0.16 0.08 0
  rotation 1 0 0 0.523599
}
