#VRML_SIM R2021a utf8
WorldInfo {
  info [
    ""
    ""
  ]
  coordinateSystem "NUE"
}
Viewpoint {
  orientation -0.25491092061367343 0.8447266413908578 0.4705925242462005 1.0202829372566962
  position 0.7482470163251665 0.33308912891080494 0.584679588704346
}
Background {
  skyColor [
    0.7 0.7 0.7
    0 0 0
    0 0 0
    0 0 0
    0 0 0
  ]
}
DEF FLOOR RectangleArena {
}
DEF real_floor Solid {
  children [
    DEF floor_shape Shape {
      geometry Box {
        size 1 0.01 1
      }
    }
    DEF floor_connector Connector {
      name "floor_connector"
      model "flippy_stick"
      boundingObject USE floor_shape
      physics Physics {
      }
      type "passive"
      autoLock TRUE
      distanceTolerance 1
      axisTolerance 3.14
      rotationTolerance 3.141592653589793
      numberOfRotations 0
      snap FALSE
    }
  ]
  boundingObject USE floor_shape
}
DEF FLIPPY Robot {
  translation 0 0.08 0
  rotation 1 0 0 0.4
  children [
    Solid {
      children [
        DEF BODY Shape {
          appearance DEF RED PBRAppearance {
            baseColor 1 0.2 0.2
            roughness 1
            metalness 0
          }
          geometry Cylinder {
            height 0.1
            radius 0.01
          }
        }
      ]
      name "solid(2)"
      boundingObject USE BODY
      physics Physics {
      }
    }
    HingeJoint {
      jointParameters DEF HINGE_PARAMS HingeJointParameters {
        anchor 0 0.05 0
      }
      device [
        RotationalMotor {
          name "M1"
        }
      ]
      endPoint DEF SPHERE1 Solid {
        translation 0 0.05 0
        rotation 1 0 0 0
        children [
          DEF S1 Shape {
            appearance DEF GREEN PBRAppearance {
              baseColor 0.2 1 0.2
              roughness 1
              metalness 0
            }
            geometry Sphere {
              radius 0.03
            }
          }
          DEF BUMPER TouchSensor {
            name "T1"
            boundingObject USE S1
            physics DEF BUMP_PHYSICS Physics {
            }
          }
          DEF sphere_connector Connector {
            name "s1_connector"
            model "flippy_stick"
            boundingObject USE S1
            physics USE BUMP_PHYSICS
            locked TRUE
            type "active"
            isLocked TRUE
            autoLock TRUE
            distanceTolerance 0.1
            axisTolerance 3.141592653589793
            rotationTolerance 3.141592653589793
            numberOfRotations 0
            snap FALSE
          }
        ]
        boundingObject USE S1
        physics DEF S_PHYSICS Physics {
        }
      }
    }
    HingeJoint {
      jointParameters HingeJointParameters {
        anchor 0 -0.05 0
      }
      device [
        RotationalMotor {
          name "M2"
        }
      ]
      endPoint DEF SPHERE2 Solid {
        translation 0 -0.05 0
        rotation 1 0 0 0
        children [
          Connector {
            name "s2_connector"
            model "flippy_stick"
            boundingObject USE S1
            physics USE BUMP_PHYSICS
            translationStep 0.1
            type "active"
            autoLock TRUE
            distanceTolerance 1
            axisTolerance 3.14
            rotationTolerance 3.14
            numberOfRotations 0
            snap FALSE
          }
          USE S1
          TouchSensor {
            name "T2"
            boundingObject USE S1
            physics USE BUMP_PHYSICS
          }
        ]
        name "solid(1)"
        boundingObject USE S1
        physics USE S_PHYSICS
      }
    }
  ]
  boundingObject USE S1
  physics USE S_PHYSICS
  controller "flippy_controller"
}
